Workbook

Sheet reference
A1: Order created at | B1: Order description | C1: Recipient name | D1: Recipient address | E1: Recipient phone | F1: proft | G1: Collected amount | H1: Total fee | I1: Order status | J1: Order status 2
A2: 45916.191 | B2: Martin 2 sole half | C2: Amit Magar | D2: Dharan, bhanu chowk | E2: 9849401180 | F2: 350 | G2: 1350 | H2: 162.38 | I2: Delivered | J2: 45918.315
A3: 45916.19 | B3: N and red 37 and 40 | C3: Prabin karki | D3: Solukhumbu tingla | E3: 9749215487 | F3: 450 | G3: 2550 | H3: 215.38 | I3: Delivered | J3: 45919.617
A4: 45895.495 | B4: Martin 1 sole 42 | C4: Smriti and Smaran store (Smriti And Smaran Store) | D4: Jorpati, Sano bazaar shop no. 25, Kathmandu,27.721747093899435, 85.37363752197368 | E4: 9847465097 | F4: 0 | G4: 0 | H4: 144.5 | I4: Returned To Merchant | J4: 45898.212
A5: 45895.34 | B5: Red Nike 40 | C5: Smriti and Smaran store (Smriti And Smaran Store) | D5: Jorpati, Sano bazaar shop no. 25, Kathmandu,27.721747093899435, 85.37363752197368 | E5: 9847465097 | F5: 0 | G5: 0 | H5: 144.5 | I5: Returned To Merchant | J5: 45898.212
A6: 45894.197 | B6: Martin 1 sole 36 | C6: Manoj | D6: Sundarijal, ktm dobato chowk | E6: 9768966994 | F6: 300 | G6: 1100 | H6: 101.75 | I6: Delivered | J6: 45894.442
A7: 45893.181 | B7: Martin 3 sole 41 | C7: Manish Bishwokarma | D7: Tanahun, dulegauda | E7: 9815193182 | F7: 650 | G7: 1650 | H7: 183.13 | I7: Delivered | J7: 45894.315
A8: 45893.179 | B8: Blue Nike 39 | C8: Rajdip Chudal | D8: Haldibari 4, magalbare jhapa | E8: 9815936372 | F8: 350 | G8: 1350 | H8: 182.38 | I8: Delivered | J8: 45895.446
A9: 45893.178 | B9: Martin 3 sole size 39 39 38 | C9: Laxmi Rai | D9: Shree antu, baral bhanjyang | E9: 9769723304 | F9: 1300 | G9: 4650 | H9: 220.63 | I9: Delivered | J9: 45898.377
A10: 45892.286 | B10: Nike 11 red and Martin 2 sole 42 and 43 | C10: Dipak Shah | D10: Tinkune, the new summit college | E10: 9826881955 | F10: 800 | G10: 2600 | H10: 105.5 | I10: Delivered | J10: 45893.253
A11: 45892.233 | B11: Red Nike 40 | C11: Bishwas | D11: Chitwan, tandi | E11: 9708251241 | F11: 0 | G11: 0 | H11: 0 | I11: Return | J11: 45895.334
A12: 45892.231 | B12: Martin 1 sole 42 | C12: Rishav Shah | D12: Birgunj, murlibagaicha | E12: 9805639259 | F12: 0 | G12: 0 | H12: 0 | I12: Return | J12: 45895.247
A13: 45892.228 | B13: Martin 1 sole 43 | C13: Chandra Bohara | D13: Dadeldhura, bagbazzar tufandadko check najik police bit | E13: 9865629618 | F13: 450 | G13: 1350 | H13: 182.38 | I13: Delivered | J13: 45895.355
... A45: 45865.178 | B45: Dark brown 40 | C45: Govinda Khatiwada | D45: Salleri bazar, solukhumbu | E45: 9869667233 | F45: 320 | G45: 1320 | H45: 212.3 | I45: Delivered | J45: 45867.602
A46: 45864.496 | C46: Smriti and Smaran store (Smriti And Smaran Store) | D46: Jorpati, Sano bazaar shop no. 25, Kathmandu,27.721747093899435, 85.37363752197368 | E46: 9847465097 | F46: 0 | G46: 0 | H46: 161.5 | I46: Returned To Merchant | J46: 45869.275
A47: 45864.205 | B47: Size 39 Martin 3 sole | C47: Rohan | D47: Manakamana suit hotel, gogechaur, banepa | E47: 9701538165 | F47: 600 | G47: 1600 | H47: 163 | I47: Delivered | J47: 45865.527
A48: 45864.204 | B48: Single sole Martin 43 | C48: Ankit Rajbanshi | D48: Mechinagar-10, dhulabari, jhapa | E48: 9827940827 | F48: 350 | G48: 1350 | H48: 182.38 | I48: Delivered | J48: 45866.45
A49: 45864.198 | B49: Martin 3 sole size 39 | C49: Kevin Tamang | D49: Chitwan, pokhara buspark | E49: 9701268575 | F49: 0 | G49: 0 | H49: 0 | I49: Return | J49: 45868.457
A50: 45864.192 | B50: Brown 40 | C50: Toshu Sah | D50: Chyasal, lalitpur | E50: 9700310751 | F50: 300 | G50: 1300 | H50: 102.25 | I50: Delivered | J50: 45865.18
A51: 45863.478 | B51: Vans 40 | C51: Smriti and Smaran store (Smriti And Smaran Store) | D51: Jorpati, Sano bazaar shop no. 25, Kathmandu,27.721747093899435, 85.37363752197368 | E51: 9847465097 | F51: 0 | G51: 0 | H51: 204 | I51: Returned To Merchant | J51: 45868.957
A52: 45863.225 | B52: Martin half double sole | C52: Abhishek rokaya | D52: Durbarmarg , yakyeti marg Jane bato | E52: 9822767923 | F52: 400 | G52: 1300 | H52: 102.25 | I52: Delivered | J52: 45863.423
A53: 45863.223 | B53: Sky blue Nike size 42 | C53: Rohan Grg Prajoo | D53: Tersapatti 3 pokhara | E53: 9705554376 | F53: 350 | G53: 1350 | H53: 162.38 | I53: Delivered | J53: 45866.33
A54: 45863.203 | B54: Red Nike 43 | C54: Sagar | D54: Dhangadhi bhakat chowk, ward no. 9 | E54: 9814660801 | F54: 350 | G54: 1350 | H54: 182.38 | I54: Delivered | J54: 45865.279
A55: 45863.202 | B55: Nike white and vans 41 | C55: Manoj Parsai | D55: Nayabazar 10, pokhara, kaski | E55: 9816148089 | F55: 950 | G55: 2550 | H55: 165.38 | I55: Delivered | J55: 45864.416
A56: 45862.197 | B56: Sr sports and vans 42 | C56: Abhishek Shrestha | D56: Tokha, kathmandu | E56: 9803226972 | F56: 900 | G56: 2500 | H56: 105.25 | I56: Delivered | J56: 45863.314
A57: 45862.195 | B57: Dark brown 42 | C57: Suraj Gyawali | D57: Parsyang pokhara | E57: 9847307560 | F57: 350 | G57: 1350 | H57: 162.38 | I57: Delivered | J57: 45863.42
A58: 45862.188 | B58: Vans 42 | C58: Bhuwan Dev | D58: Soil management dictorate harihar bhawan, lalitpur | E58: 9766381427 | F58: 700 | G58: 1300 | H58: 102.25 | I58: Delivered | J58: 45863.283
A59: 45861.205 | C59: Srawon Magar | D59: Sindhuli bazzar, kabiram | E59: 9844184404 | F59: 0 | G59: 0 | H59: 0 | I59: Return | J59: 45864.38
A60: 45861.201 | B60: Dunk Low pro 39 | C60: Arpan Neupane | D60: Kharaney path, leknath kaski | E60: 9846952971 | F60: 350 | G60: 1350 | H60: 162.38 | I60: Delivered | J60: 45862.362
A61: 45861.199 | B61: Vans 41 | C61: Menal Shrestha | D61: Steel Tower, jawalakhel | E61: 9818994553 | F61: 700 | G61: 1300 | H61: 102.25 | I61: Delivered | J61: 45861.444
A62: 45860.993 | B62: Vans size 40 | C62: Arjun | D62: Simara, iccha hotel | E62: 9824283470 | F62: 0 | G62: 0 | H62: 182.38 | I62: Pickup Cancel | J62: 45863.422
A63: 45860.511 | B63: Sr delta size 39 | C63: Sanjit Tamang | D63: Sirutar, bhaktapur | E63: 9826764749 | F63: 300 | G63: 1300 | H63: 102.25 | I63: Delivered | J63: 45862.395
A64: 45860.138 | B64: Sr delta size 39 | C64: Smriti and Smaran store (Smriti And Smaran Store) | D64: Jorpati, Sano bazaar shop no. 25, Kathmandu,27.721747093899435, 85.37363752197368 | E64: 9847465097 | F64: 0 | G64: 0 | H64: 42.5 | I64: Returned To Merchant | J64: 45863.213
A65: 45859.484 | B65: Vans 41 | C65: Smriti and Smaran store (Smriti And Smaran Store) | D65: Jorpati, Sano bazaar shop no. 25, Kathmandu,27.721747093899435, 85.37363752197368 | E65: 9847465097 | F65: 0 | G65: 0 | H65: 204 | I65: Returned To Merchant | J65: 45873.684
A66: 45858.192 | B66: Sr delta size 39 | C66: Sanjit Tamang | D66: Sirutar, bhaktapur | E66: 9826764749 | F66: 0 | G66: 0 | H66: 0 | I66: Return | J66: 45860.135
A67: 45857.228 | B67: Vans 43 | C67: Newar Shyam | D67: Pakhapani, dang | E67: 9843713594 | F67: 750 | G67: 1350 | H67: 232.38 | I67: Delivered | J67: 45860.518
A68: 45857.209 | B68: Gray 42 | C68: Diwash | D68: Morang pathari | E68: 9746898035 | F68: 450 | G68: 1450 | H68: 232.63 | I68: Delivered | J68: 45862.316
A69: 45857.207 | B69: Vans 40 | C69: Arjun | D69: Simara, iccha hotel | E69: 9824283470 | F69: 0 | G69: 0 | H69: 0 | I69: Return | J69: 45863.394
A70: 45857.206 | B70: Nike White and gray 43 | C70: Nishan sigdel | D70: Sunsari, ramdhuni bhasi, lalpur | E70: 9829369398 | F70: 450 | G70: 2450 | H70: 215.13 | I70: Delivered | J70: 45860.334
A71: 45857.199 | B71: Brown 39 nike | C71: Samir Khadka | D71: Mullani, manakamana mandir | E71: 9803441330 | F71: 300 | G71: 1300 | H71: 152.25 | I71: Delivered | J71: 45858.386
...

Sheet balance sheet
B2: Month | C2: Cost price | D2: profit margin | E2: ad cost | F2: net profit | G2: Revenue | H2: Gross Profit | I2: D fee | J2: R fee | K2: Total fee | L2: Delivered Orders | M2: Returned Orders | N2: Total Orders | O2: Delivery Rate | P2: Return Rate | Q2: Active Days | R2: Inactive Days | S2: Most Order Created Date
B3: **January** | C3: =G3-H3 -> 0 | D3: =IFERROR(H3/C3*100, 0) -> 0 | E3: 0 | F3: ='balance sheet'!H3-'balance sheet'!I3-'balance sheet'!E3-'balance sheet'!J3 -> 0 | G3: 0 | H3: 0 | I3: 0 | J3: 0 | K3: 0 | L3: 0 | M3: 0 | N3: 0 | O3: 0 | P3: 0 | Q3: 0 | R3: 31 | S3: N/A
B4: **February** | C4: =G4-H4 -> 0 | D4: =IFERROR(H4/C4*100, 0) -> 0 | E4: 0 | F4: ='balance sheet'!H4-'balance sheet'!I4-'balance sheet'!E4-'balance sheet'!J4 -> 0 | G4: 0 | H4: 0 | I4: 0 | K4: 0 | L4: 0 | M4: 0 | N4: 0 | O4: 0 | P4: 0 | Q4: 0 | R4: 28 | S4: N/A
B5: **March** | C5: =G5-H5 -> 0 | D5: =IFERROR(H5/C5*100, 0) -> 0 | E5: 0 | F5: ='balance sheet'!H5-'balance sheet'!I5-'balance sheet'!E5-'balance sheet'!J5 -> 0 | G5: 0 | H5: 0 | I5: 0 | J5: 0 | K5: 0 | L5: 0 | M5: 0 | N5: 0 | O5: 0 | P5: 0 | Q5: 0 | R5: 31 | S5: N/A
B6: **April** | C6: =G6-H6 -> 20650 | D6: =IFERROR(H6/C6*100, 0) -> 42.615012 | E6: 5156.2 | F6: ='balance sheet'!H6-'balance sheet'!I6-'balance sheet'!E6-'balance sheet'!J6 -> 3503.02 | G6: 29450 | H6: 8800 | I6: 73.63 | J6: 67.15 | K6: 140.78 | L6: 19 | M6: 1 | N6: 20 | O6: 0.95 | P6: 0.05 | Q6: 6 | R6: 24 | S6: 2025-04-30 (7)
B7: **May** | C7: =G7-H7 -> 35100 | D7: =IFERROR(H7/C7*100, 0) -> 26.695157 | E7: 14893.2 | F7: ='balance sheet'!H7-'balance sheet'!I7-'balance sheet'!E7-'balance sheet'!J7 -> -6709.08 | G7: 44470 | H7: 9370 | I7: 940.18 | J7: 245.7 | K7: 1185.88 | L7: 31 | M7: 6 | N7: 37 | O7: 0.8378 | P7: 0.1622 | Q7: 9 | R7: 22 | S7: 2025-05-29 (12)
B8: **June** | C8: =G8-H8 -> 17600 | D8: =IFERROR(H8/C8*100, 0) -> 48.579545 | E8: 3032.4 | F8: ='balance sheet'!H8-'balance sheet'!I8-'balance sheet'!E8-'balance sheet'!J8 -> 4020.17 | G8: 26150 | H8: 8550 | I8: 1348.38 | J8: 149.05 | K8: 1497.43 | L8: 17 | M8: 3 | N8: 20 | O8: 0.85 | P8: 0.15 | Q8: 4 | R8: 26 | S8: 2025-06-03 (11)
B9: **July** | C9: =G9-H9 -> 29000 | D9: =IFERROR(H9/C9*100, 0) -> 47.310345 | E9: 12684 | F9: ='balance sheet'!H9-'balance sheet'!I9-'balance sheet'!E9-'balance sheet'!J9 -> -4434.37 | G9: 42720 | H9: 13720 | I9: 4628.87 | J9: 841.5 | K9: 5470.37 | L9: 28 | M9: 5 | N9: 33 | O9: 0.8485 | P9: 0.1515 | Q9: 9 | R9: 22 | S9: 2025-07-19 (6)
B10: **August** | C10: =G10-H10 -> 29450 | D10: =IFERROR(H10/C10*100, 0) -> 46.519525 | E10: 6903.4 | F10: ='balance sheet'!H10-'balance sheet'!I10-'balance sheet'!E10-'balance sheet'!J10 -> 532.13 | G10: 43150 | H10: 13700 | I10: 4342.97 | J10: 1921.5 | K10: 6264.47 | L10: 26 | M10: 13 | N10: 39 | O10: 0.6667 | P10: 0.3333 | Q10: 12 | R10: 19 | S10: 2025-08-24 (5)
B11: **September** | C11: =G11-H11 -> 3100 | D11: =IFERROR(H11/C11*100, 0) -> 25.806452 | E11: 270.2 | F11: ='balance sheet'!H11-'balance sheet'!I11-'balance sheet'!E11-'balance sheet'!J11 -> 152.04 | G11: 3900 | H11: 800 | I11: 377.76 | J11: 0 | K11: 377.76 | L11: 2 | M11: 0 | N11: 2 | O11: 1 | P11: 0 | Q11: 1 | R11: 29 | S11: 2025-09-16 (2)
B12: **October** | C12: =G12-H12 -> 0 | D12: =IFERROR(H12/C12*100, 0) -> 0 | E12: 0 | F12: ='balance sheet'!H12-'balance sheet'!I12-'balance sheet'!E12-'balance sheet'!J12 -> 0 | G12: 0 | H12: 0 | I12: 0 | J12: 0 | K12: 0 | L12: 0 | M12: 0 | N12: 0 | O12: 0 | P12: 0 | Q12: 0 | R12: 31 | S12: N/A
B13: **November** | C13: =G13-H13 -> 0 | D13: =IFERROR(H13/C13*100, 0) -> 0 | E13: 0 | F13: ='balance sheet'!H13-'balance sheet'!I13-'balance sheet'!E13-'balance sheet'!J13 -> 0 | G13: 0 | H13: 0 | I13: 0 | J13: 0 | K13: 0 | L13: 0 | M13: 0 | N13: 0 | O13: 0 | P13: 0 | Q13: 0 | R13: 30 | S13: N/A
B14: **December** | C14: =G14-H14 -> 0 | D14: =IFERROR(H14/C14*100, 0) -> 0 | E14: 0 | F14: ='balance sheet'!H14-'balance sheet'!I14-'balance sheet'!E14-'balance sheet'!J14 -> 0 | G14: 0 | H14: 0 | I14: 0 | J14: 0 | K14: 0 | L14: 0 | M14: 0 | N14: 0 | O14: 0 | P14: 0 | Q14: 0 | R14: 31 | S14: N/A
B15: **Total** | C15: =sum(C6:C11) -> 134900 | D15: =AVERAGE(D6:D11) -> 39.587673 | E15: 42939.4 | F15: =SUM(F3:F14) -> -2936.09 | G15: **189,840** | H15: **54,940** | I15: **11,711.79** | J15: **3,224.90** | K15: **14,936.69** | L15: **123** | M15: **28** | N15: **151** | O15: **81.46%** | P15: **18.54%** | Q15: **41** | R15: **324** | S15: **-**

Sheet checklist1
A1: =IFERROR(__xludf.DUMMYFUNCTION("QUERY(reference!A1:J188, ""where I = 'Delivered'"", 1)"),"Order created at") -> Order created at | B1: =IFERROR(__xludf.DUMMYFUNCTION("""COMPUTED_VALUE"""),"Order description") -> Order description | C1: =IFERROR(__xludf.DUMMYFUNCTION("""COMPUTED_VALUE"""),"Recipient name") -> Recipient name | D1: =IFERROR(__xludf.DUMMYFUNCTION("""COMPUTED_VALUE"""),"Recipient address") -> Recipient address | E1: =IFERROR(__xludf.DUMMYFUNCTION("""COMPUTED_VALUE"""),"Recipient phone") -> Recipient phone | F1: =IFERROR(__xludf.DUMMYFUNCTION("""COMPUTED_VALUE"""),"proft") -> proft | G1: =IFERROR(__xludf.DUMMYFUNCTION("""COMPUTED_VALUE"""),"Collected amount") -> Collected amount | H1: =IFERROR(__xludf.DUMMYFUNCTION("""COMPUTED_VALUE"""),"Total fee") -> Total fee | I1: =IFERROR(__xludf.DUMMYFUNCTION("""COMPUTED_VALUE"""),"Order status") -> Order status | J1: =IFERROR(__xludf.DUMMYFUNCTION("""COMPUTED_VALUE"""),"Order status") -> Order status
A2: =IFERROR(__xludf.DUMMYFUNCTION("""COMPUTED_VALUE"""),45916.191412037035) -> 45916.191 | B2: =IFERROR(__xludf.DUMMYFUNCTION("""COMPUTED_VALUE"""),"Martin 2 sole half ") -> Martin 2 sole half | C2: =IFERROR(__xludf.DUMMYFUNCTION("""COMPUTED_VALUE"""),"Amit Magar") -> Amit Magar | D2: =IFERROR(__xludf.DUMMYFUNCTION("""COMPUTED_VALUE"""),"Dharan, bhanu chowk ") -> Dharan, bhanu chowk | E2: =IFERROR(__xludf.DUMMYFUNCTION("""COMPUTED_VALUE"""),9.84940118E9) -> 9849401180 | F2: =IFERROR(__xludf.DUMMYFUNCTION("""COMPUTED_VALUE"""),350.0) -> 350 | G2: =IFERROR(__xludf.DUMMYFUNCTION("""COMPUTED_VALUE"""),1350.0) -> 1350 | H2: =IFERROR(__xludf.DUMMYFUNCTION("""COMPUTED_VALUE"""),162.38) -> 162.38 | I2: =IFERROR(__xludf.DUMMYFUNCTION("""COMPUTED_VALUE"""),"Delivered") -> Delivered | J2: =IFERROR(__xludf.DUMMYFUNCTION("""COMPUTED_VALUE"""),45918.31509259259) -> 45918.315
A3: =IFERROR(__xludf.DUMMYFUNCTION("""COMPUTED_VALUE"""),45916.18975694444) -> 45916.19 | B3: =IFERROR(__xludf.DUMMYFUNCTION("""COMPUTED_VALUE"""),"N and red 37 and 40") -> N and red 37 and 40 | C3: =IFERROR(__xludf.DUMMYFUNCTION("""COMPUTED_VALUE"""),"Prabin karki") -> Prabin karki | D3: =IFERROR(__xludf.DUMMYFUNCTION("""COMPUTED_VALUE"""),"Solukhumbu tingla") -> Solukhumbu tingla | E3: =IFERROR(__xludf.DUMMYFUNCTION("""COMPUTED_VALUE"""),9.749215487E9) -> 9749215487 | F3: =IFERROR(__xludf.DUMMYFUNCTION("""COMPUTED_VALUE"""),450.0) -> 450 | G3: =IFERROR(__xludf.DUMMYFUNCTION("""COMPUTED_VALUE"""),2550.0) -> 2550 | H3: =IFERROR(__xludf.DUMMYFUNCTION("""COMPUTED_VALUE"""),215.38) -> 215.38 | I3: =IFERROR(__xludf.DUMMYFUNCTION("""COMPUTED_VALUE"""),"Delivered") -> Delivered | J3: =IFERROR(__xludf.DUMMYFUNCTION("""COMPUTED_VALUE"""),45919.61679398148) -> 45919.617
A4: =IFERROR(__xludf.DUMMYFUNCTION("""COMPUTED_VALUE"""),45894.19651620371) -> 45894.197 | B4: =IFERROR(__xludf.DUMMYFUNCTION("""COMPUTED_VALUE"""),"Martin 1 sole 36") -> Martin 1 sole 36 | C4: =IFERROR(__xludf.DUMMYFUNCTION("""COMPUTED_VALUE"""),"Manoj") -> Manoj | D4: =IFERROR(__xludf.DUMMYFUNCTION("""COMPUTED_VALUE"""),"Sundarijal, ktm dobato chowk") -> Sundarijal, ktm dobato chowk | E4: =IFERROR(__xludf.DUMMYFUNCTION("""COMPUTED_VALUE"""),9.768966994E9) -> 9768966994 | F4: =IFERROR(__xludf.DUMMYFUNCTION("""COMPUTED_VALUE"""),300.0) -> 300 | G4: =IFERROR(__xludf.DUMMYFUNCTION("""COMPUTED_VALUE"""),1100.0) -> 1100 | H4: =IFERROR(__xludf.DUMMYFUNCTION("""COMPUTED_VALUE"""),101.75) -> 101.75 | I4: =IFERROR(__xludf.DUMMYFUNCTION("""COMPUTED_VALUE"""),"Delivered") -> Delivered | J4: =IFERROR(__xludf.DUMMYFUNCTION("""COMPUTED_VALUE"""),45894.44189814814) -> 45894.442
A5: =IFERROR(__xludf.DUMMYFUNCTION("""COMPUTED_VALUE"""),45893.18133101852) -> 45893.181 | B5: =IFERROR(__xludf.DUMMYFUNCTION("""COMPUTED_VALUE"""),"Martin 3 sole 41") -> Martin 3 sole 41 | C5: =IFERROR(__xludf.DUMMYFUNCTION("""COMPUTED_VALUE"""),"Manish Bishwokarma") -> Manish Bishwokarma | D5: =IFERROR(__xludf.DUMMYFUNCTION("""COMPUTED_VALUE"""),"Tanahun, dulegauda ") -> Tanahun, dulegauda | E5: =IFERROR(__xludf.DUMMYFUNCTION("""COMPUTED_VALUE"""),9.815193182E9) -> 9815193182 | F5: =IFERROR(__xludf.DUMMYFUNCTION("""COMPUTED_VALUE"""),650.0) -> 650 | G5: =IFERROR(__xludf.DUMMYFUNCTION("""COMPUTED_VALUE"""),1650.0) -> 1650 | H5: =IFERROR(__xludf.DUMMYFUNCTION("""COMPUTED_VALUE"""),183.13) -> 183.13 | I5: =IFERROR(__xludf.DUMMYFUNCTION("""COMPUTED_VALUE"""),"Delivered") -> Delivered | J5: =IFERROR(__xludf.DUMMYFUNCTION("""COMPUTED_VALUE"""),45894.3146412037) -> 45894.315
A6: =IFERROR(__xludf.DUMMYFUNCTION("""COMPUTED_VALUE"""),45893.17900462963) -> 45893.179 | B6: =IFERROR(__xludf.DUMMYFUNCTION("""COMPUTED_VALUE"""),"Blue Nike 39") -> Blue Nike 39 | C6: =IFERROR(__xludf.DUMMYFUNCTION("""COMPUTED_VALUE"""),"Rajdip Chudal") -> Rajdip Chudal | D6: =IFERROR(__xludf.DUMMYFUNCTION("""COMPUTED_VALUE"""),"Haldibari 4, magalbare jhapa") -> Haldibari 4, magalbare jhapa | E6: =IFERROR(__xludf.DUMMYFUNCTION("""COMPUTED_VALUE"""),9.815936372E9) -> 9815936372 | F6: =IFERROR(__xludf.DUMMYFUNCTION("""COMPUTED_VALUE"""),350.0) -> 350 | G6: =IFERROR(__xludf.DUMMYFUNCTION("""COMPUTED_VALUE"""),1350.0) -> 1350 | H6: =IFERROR(__xludf.DUMMYFUNCTION("""COMPUTED_VALUE"""),182.38) -> 182.38 | I6: =IFERROR(__xludf.DUMMYFUNCTION("""COMPUTED_VALUE"""),"Delivered") -> Delivered | J6: =IFERROR(__xludf.DUMMYFUNCTION("""COMPUTED_VALUE"""),45895.44592592593) -> 45895.446
A7: =IFERROR(__xludf.DUMMYFUNCTION("""COMPUTED_VALUE"""),45893.178032407406) -> 45893.178 | B7: =IFERROR(__xludf.DUMMYFUNCTION("""COMPUTED_VALUE"""),"Martin 3 sole size 39 39 38") -> Martin 3 sole size 39 39 38 | C7: =IFERROR(__xludf.DUMMYFUNCTION("""COMPUTED_VALUE"""),"Laxmi Rai") -> Laxmi Rai | D7: =IFERROR(__xludf.DUMMYFUNCTION("""COMPUTED_VALUE""")," Shree antu, baral bhanjyang") -> Shree antu, baral bhanjyang | E7: =IFERROR(__xludf.DUMMYFUNCTION("""COMPUTED_VALUE"""),9.769723304E9) -> 9769723304 | F7: =IFERROR(__xludf.DUMMYFUNCTION("""COMPUTED_VALUE"""),1300.0) -> 1300 | G7: =IFERROR(__xludf.DUMMYFUNCTION("""COMPUTED_VALUE"""),4650.0) -> 4650 | H7: =IFERROR(__xludf.DUMMYFUNCTION("""COMPUTED_VALUE"""),220.63) -> 220.63 | I7: =IFERROR(__xludf.DUMMYFUNCTION("""COMPUTED_VALUE"""),"Delivered") -> Delivered | J7: =IFERROR(__xludf.DUMMYFUNCTION("""COMPUTED_VALUE"""),45898.376655092594) -> 45898.377
A8: =IFERROR(__xludf.DUMMYFUNCTION("""COMPUTED_VALUE"""),45892.28570601852) -> 45892.286 | B8: =IFERROR(__xludf.DUMMYFUNCTION("""COMPUTED_VALUE"""),"Nike 11 red and Martin 2 sole 42 and 43") -> Nike 11 red and Martin 2 sole 42 and 43 | C8: =IFERROR(__xludf.DUMMYFUNCTION("""COMPUTED_VALUE"""),"Dipak Shah") -> Dipak Shah | D8: =IFERROR(__xludf.DUMMYFUNCTION("""COMPUTED_VALUE"""),"Tinkune, the new summit college") -> Tinkune, the new summit college | E8: =IFERROR(__xludf.DUMMYFUNCTION("""COMPUTED_VALUE"""),9.826881955E9) -> 9826881955 | F8: =IFERROR(__xludf.DUMMYFUNCTION("""COMPUTED_VALUE"""),800.0) -> 800 | G8: =IFERROR(__xludf.DUMMYFUNCTION("""COMPUTED_VALUE"""),2600.0) -> 2600 | H8: =IFERROR(__xludf.DUMMYFUNCTION("""COMPUTED_VALUE"""),105.5) -> 105.5 | I8: =IFERROR(__xludf.DUMMYFUNCTION("""COMPUTED_VALUE"""),"Delivered") -> Delivered | J8: =IFERROR(__xludf.DUMMYFUNCTION("""COMPUTED_VALUE"""),45893.2530324074) -> 45893.253
A9: =IFERROR(__xludf.DUMMYFUNCTION("""COMPUTED_VALUE"""),45892.228217592594) -> 45892.228 | B9: =IFERROR(__xludf.DUMMYFUNCTION("""COMPUTED_VALUE"""),"Martin 1 sole 43") -> Martin 1 sole 43 | C9: =IFERROR(__xludf.DUMMYFUNCTION("""COMPUTED_VALUE"""),"Chandra Bohara") -> Chandra Bohara | D9: =IFERROR(__xludf.DUMMYFUNCTION("""COMPUTED_VALUE"""),"Dadeldhura, bagbazzar tufandadko check najik police bit") -> Dadeldhura, bagbazzar tufandadko check najik police bit | E9: =IFERROR(__xludf.DUMMYFUNCTION("""COMPUTED_VALUE"""),9.865629618E9) -> 9865629618 | F9: =IFERROR(__xludf.DUMMYFUNCTION("""COMPUTED_VALUE"""),450.0) -> 450 | G9: =IFERROR(__xludf.DUMMYFUNCTION("""COMPUTED_VALUE"""),1350.0) -> 1350 | H9: =IFERROR(__xludf.DUMMYFUNCTION("""COMPUTED_VALUE"""),182.38) -> 182.38 | I9: =IFERROR(__xludf.DUMMYFUNCTION("""COMPUTED_VALUE"""),"Delivered") -> Delivered | J9: =IFERROR(__xludf.DUMMYFUNCTION("""COMPUTED_VALUE"""),45895.355046296296) -> 45895.355
A10: =IFERROR(__xludf.DUMMYFUNCTION("""COMPUTED_VALUE"""),45892.22659722222) -> 45892.227 | B10: =IFERROR(__xludf.DUMMYFUNCTION("""COMPUTED_VALUE"""),"Martin 2 sole 40") -> Martin 2 sole 40 | C10: =IFERROR(__xludf.DUMMYFUNCTION("""COMPUTED_VALUE"""),"Prabin Karki") -> Prabin Karki | D10: =IFERROR(__xludf.DUMMYFUNCTION("""COMPUTED_VALUE"""),"Solukhumbu, tingla") -> Solukhumbu, tingla | E10: =IFERROR(__xludf.DUMMYFUNCTION("""COMPUTED_VALUE"""),9.749215487E9) -> 9749215487 | F10: =IFERROR(__xludf.DUMMYFUNCTION("""COMPUTED_VALUE"""),550.0) -> 550 | G10: =IFERROR(__xludf.DUMMYFUNCTION("""COMPUTED_VALUE"""),1550.0) -> 1550 | H10: =IFERROR(__xludf.DUMMYFUNCTION("""COMPUTED_VALUE"""),212.88) -> 212.88 | I10: =IFERROR(__xludf.DUMMYFUNCTION("""COMPUTED_VALUE"""),"Delivered") -> Delivered | J10: =IFERROR(__xludf.DUMMYFUNCTION("""COMPUTED_VALUE"""),45898.67103009259) -> 45898.671
A11: =IFERROR(__xludf.DUMMYFUNCTION("""COMPUTED_VALUE"""),45891.18746527778) -> 45891.187 | B11: =IFERROR(__xludf.DUMMYFUNCTION("""COMPUTED_VALUE"""),"Blue Nike size 42") -> Blue Nike size 42 | C11: =IFERROR(__xludf.DUMMYFUNCTION("""COMPUTED_VALUE"""),"Biraj Tamang") -> Biraj Tamang | D11: =IFERROR(__xludf.DUMMYFUNCTION("""COMPUTED_VALUE"""),"Jhapa, budhabare or buddhashanti ") -> Jhapa, budhabare or buddhashanti | E11: =IFERROR(__xludf.DUMMYFUNCTION("""COMPUTED_VALUE"""),9.702839214E9) -> 9702839214 | F11: =IFERROR(__xludf.DUMMYFUNCTION("""COMPUTED_VALUE"""),350.0) -> 350 | G11: =IFERROR(__xludf.DUMMYFUNCTION("""COMPUTED_VALUE"""),1350.0) -> 1350 | H11: =IFERROR(__xludf.DUMMYFUNCTION("""COMPUTED_VALUE"""),182.38) -> 182.38 | I11: =IFERROR(__xludf.DUMMYFUNCTION("""COMPUTED_VALUE"""),"Delivered") -> Delivered | J11: =IFERROR(__xludf.DUMMYFUNCTION("""COMPUTED_VALUE"""),45894.39797453704) -> 45894.398
A12: =IFERROR(__xludf.DUMMYFUNCTION("""COMPUTED_VALUE"""),45891.18523148148) -> 45891.185 | B12: =IFERROR(__xludf.DUMMYFUNCTION("""COMPUTED_VALUE"""),"Red Nike 40") -> Red Nike 40 | C12: =IFERROR(__xludf.DUMMYFUNCTION("""COMPUTED_VALUE"""),"Sujan Jagebu Limbu") -> Sujan Jagebu Limbu | D12: =IFERROR(__xludf.DUMMYFUNCTION("""COMPUTED_VALUE"""),"Jhapa, birtamod karat chowk Road no 1") -> Jhapa, birtamod karat chowk Road no 1 | E12: =IFERROR(__xludf.DUMMYFUNCTION("""COMPUTED_VALUE"""),9.700427269E9) -> 9700427269 | F12: =IFERROR(__xludf.DUMMYFUNCTION("""COMPUTED_VALUE"""),450.0) -> 450 | G12: =IFERROR(__xludf.DUMMYFUNCTION("""COMPUTED_VALUE"""),1350.0) -> 1350 | H12: =IFERROR(__xludf.DUMMYFUNCTION("""COMPUTED_VALUE"""),182.38) -> 182.38 | I12: =IFERROR(__xludf.DUMMYFUNCTION("""COMPUTED_VALUE"""),"Delivered") -> Delivered | J12: =IFERROR(__xludf.DUMMYFUNCTION("""COMPUTED_VALUE"""),45893.449965277774) -> 45893.45
A13: =IFERROR(__xludf.DUMMYFUNCTION("""COMPUTED_VALUE"""),45890.17833333333) -> 45890.178 | B13: =IFERROR(__xludf.DUMMYFUNCTION("""COMPUTED_VALUE"""),"Casual Adidas shoes 41") -> Casual Adidas shoes 41 | C13: =IFERROR(__xludf.DUMMYFUNCTION("""COMPUTED_VALUE"""),"Asmirt Tamang") -> Asmirt Tamang | D13: =IFERROR(__xludf.DUMMYFUNCTION("""COMPUTED_VALUE"""),"Pokhara") -> Pokhara | E13: =IFERROR(__xludf.DUMMYFUNCTION("""COMPUTED_VALUE"""),9.703252518E9) -> 9703252518 | F13: =IFERROR(__xludf.DUMMYFUNCTION("""COMPUTED_VALUE"""),450.0) -> 450 | G13: =IFERROR(__xludf.DUMMYFUNCTION("""COMPUTED_VALUE"""),1450.0) -> 1450 | H13: =IFERROR(__xludf.DUMMYFUNCTION("""COMPUTED_VALUE"""),162.63) -> 162.63 | I13: =IFERROR(__xludf.DUMMYFUNCTION("""COMPUTED_VALUE"""),"Delivered") -> Delivered | J13: =IFERROR(__xludf.DUMMYFUNCTION("""COMPUTED_VALUE"""),45893.31458333333) -> 45893.315
A14: =IFERROR(__xludf.DUMMYFUNCTION("""COMPUTED_VALUE"""),45890.17673611111) -> 45890.177 | B14: =IFERROR(__xludf.DUMMYFUNCTION("""COMPUTED_VALUE"""),"Martin 2 sole 39 nayabasti") -> Martin 2 sole 39 nayabasti | C14: =IFERROR(__xludf.DUMMYFUNCTION("""COMPUTED_VALUE"""),"Anil Khadgi") -> Anil Khadgi | D14: =IFERROR(__xludf.DUMMYFUNCTION("""COMPUTED_VALUE"""),"Sitapaila mathi ramkot") -> Sitapaila mathi ramkot | E14: =IFERROR(__xludf.DUMMYFUNCTION("""COMPUTED_VALUE"""),9.803874775E9) -> 9803874775 | F14: =IFERROR(__xludf.DUMMYFUNCTION("""COMPUTED_VALUE"""),500.0) -> 500 | G14: =IFERROR(__xludf.DUMMYFUNCTION("""COMPUTED_VALUE"""),1500.0) -> 1500 | H14: =IFERROR(__xludf.DUMMYFUNCTION("""COMPUTED_VALUE"""),102.75) -> 102.75 | I14: =IFERROR(__xludf.DUMMYFUNCTION("""COMPUTED_VALUE"""),"Delivered") -> Delivered | J14: =IFERROR(__xludf.DUMMYFUNCTION("""COMPUTED_VALUE"""),45890.50582175926) -> 45890.506
A15: =IFERROR(__xludf.DUMMYFUNCTION("""COMPUTED_VALUE"""),45890.17537037037) -> 45890.175 | B15: =IFERROR(__xludf.DUMMYFUNCTION("""COMPUTED_VALUE"""),"Martin 3 sole size 43") -> Martin 3 sole size 43 | C15: =IFERROR(__xludf.DUMMYFUNCTION("""COMPUTED_VALUE"""),"Bikash") -> Bikash | D15: =IFERROR(__xludf.DUMMYFUNCTION("""COMPUTED_VALUE"""),"Rolpa, ghartghau") -> Rolpa, ghartghau | E15: =IFERROR(__xludf.DUMMYFUNCTION("""COMPUTED_VALUE"""),9.765840359E9) -> 9765840359 | F15: =IFERROR(__xludf.DUMMYFUNCTION("""COMPUTED_VALUE"""),650.0) -> 650 | G15: =IFERROR(__xludf.DUMMYFUNCTION("""COMPUTED_VALUE"""),1650.0) -> 1650 | H15: =IFERROR(__xludf.DUMMYFUNCTION("""COMPUTED_VALUE"""),213.13) -> 213.13 | I15: =IFERROR(__xludf.DUMMYFUNCTION("""COMPUTED_VALUE"""),"Delivered") -> Delivered | J15: =IFERROR(__xludf.DUMMYFUNCTION("""COMPUTED_VALUE"""),45895.638506944444) -> 45895.639
A16: =IFERROR(__xludf.DUMMYFUNCTION("""COMPUTED_VALUE"""),45889.17605324074) -> 45889.176 | B16: =IFERROR(__xludf.DUMMYFUNCTION("""COMPUTED_VALUE"""),"Chelsea size 43") -> Chelsea size 43 | C16: =IFERROR(__xludf.DUMMYFUNCTION("""COMPUTED_VALUE"""),"Dipendra Chaudhari") -> Dipendra Chaudhari | D16: =IFERROR(__xludf.DUMMYFUNCTION("""COMPUTED_VALUE"""),"Chitwan, madi") -> Chitwan, madi | E16: =IFERROR(__xludf.DUMMYFUNCTION("""COMPUTED_VALUE"""),9.807289391E9) -> 9807289391 | F16: =IFERROR(__xludf.DUMMYFUNCTION("""COMPUTED_VALUE"""),450.0) -> 450 | G16: =IFERROR(__xludf.DUMMYFUNCTION("""COMPUTED_VALUE"""),1450.0) -> 1450 | H16: =IFERROR(__xludf.DUMMYFUNCTION("""COMPUTED_VALUE"""),162.63) -> 162.63 | I16: =IFERROR(__xludf.DUMMYFUNCTION("""COMPUTED_VALUE"""),"Delivered") -> Delivered | J16: =IFERROR(__xludf.DUMMYFUNCTION("""COMPUTED_VALUE"""),45891.61177083333) -> 45891.612
A17: =IFERROR(__xludf.DUMMYFUNCTION("""COMPUTED_VALUE"""),45889.1749074074) -> 45889.175 | B17: =IFERROR(__xludf.DUMMYFUNCTION("""COMPUTED_VALUE"""),"Martin 3 sole size 41") -> Martin 3 sole size 41 | C17: =IFERROR(__xludf.DUMMYFUNCTION("""COMPUTED_VALUE"""),"Ninam Rai") -> Ninam Rai | D17: =IFERROR(__xludf.DUMMYFUNCTION("""COMPUTED_VALUE"""),"Taplejung") -> Taplejung | E17: =IFERROR(__xludf.DUMMYFUNCTION("""COMPUTED_VALUE"""),9.767381711E9) -> 9767381711 | F17: =IFERROR(__xludf.DUMMYFUNCTION("""COMPUTED_VALUE"""),550.0) -> 550 | G17: =IFERROR(__xludf.DUMMYFUNCTION("""COMPUTED_VALUE"""),1550.0) -> 1550 | H17: =IFERROR(__xludf.DUMMYFUNCTION("""COMPUTED_VALUE"""),212.88) -> 212.88 | I17: =IFERROR(__xludf.DUMMYFUNCTION("""COMPUTED_VALUE"""),"Delivered") -> Delivered | J17: =IFERROR(__xludf.DUMMYFUNCTION("""COMPUTED_VALUE"""),45895.23165509259) -> 45895.232
A18: =IFERROR(__xludf.DUMMYFUNCTION("""COMPUTED_VALUE"""),45889.17271990741) -> 45889.173 | B18: =IFERROR(__xludf.DUMMYFUNCTION("""COMPUTED_VALUE"""),"Converse black size 40") -> Converse black size 40 | C18: =IFERROR(__xludf.DUMMYFUNCTION("""COMPUTED_VALUE"""),"Ajeet Khadka") -> Ajeet Khadka | D18: =IFERROR(__xludf.DUMMYFUNCTION("""COMPUTED_VALUE"""),"Bhaktapur, bageswari changunarayan nabarpalika wada no 7") -> Bhaktapur, bageswari changunarayan nabarpalika wada no 7 | E18: =IFERROR(__xludf.DUMMYFUNCTION("""COMPUTED_VALUE"""),9.860944595E9) -> 9860944595 | F18: =IFERROR(__xludf.DUMMYFUNCTION("""COMPUTED_VALUE"""),500.0) -> 500 | G18: =IFERROR(__xludf.DUMMYFUNCTION("""COMPUTED_VALUE"""),1300.0) -> 1300 | H18: =IFERROR(__xludf.DUMMYFUNCTION("""COMPUTED_VALUE"""),182.25) -> 182.25 | I18: =IFERROR(__xludf.DUMMYFUNCTION("""COMPUTED_VALUE"""),"Delivered") -> Delivered | J18: =IFERROR(__xludf.DUMMYFUNCTION("""COMPUTED_VALUE"""),45890.36565972222) -> 45890.366
A19: =IFERROR(__xludf.DUMMYFUNCTION("""COMPUTED_VALUE"""),45888.17891203704) -> 45888.179 | B19: =IFERROR(__xludf.DUMMYFUNCTION("""COMPUTED_VALUE"""),"Martin single 41 and 42") -> Martin single 41 and 42 | C19: =IFERROR(__xludf.DUMMYFUNCTION("""COMPUTED_VALUE"""),"Sitaram Pun") -> Sitaram Pun | D19: =IFERROR(__xludf.DUMMYFUNCTION("""COMPUTED_VALUE"""),"Pyuthan, sari") -> Pyuthan, sari | E19: =IFERROR(__xludf.DUMMYFUNCTION("""COMPUTED_VALUE"""),9.762095448E9) -> 9762095448 | F19: =IFERROR(__xludf.DUMMYFUNCTION("""COMPUTED_VALUE"""),550.0) -> 550 | G19: =IFERROR(__xludf.DUMMYFUNCTION("""COMPUTED_VALUE"""),2550.0) -> 2550 | H19: =IFERROR(__xludf.DUMMYFUNCTION("""COMPUTED_VALUE"""),185.38) -> 185.38 | I19: =IFERROR(__xludf.DUMMYFUNCTION("""COMPUTED_VALUE"""),"Delivered") -> Delivered | J19: =IFERROR(__xludf.DUMMYFUNCTION("""COMPUTED_VALUE"""),45893.495370370365) -> 45893.495
A20: =IFERROR(__xludf.DUMMYFUNCTION("""COMPUTED_VALUE"""),45888.17722222222) -> 45888.177 | B20: =IFERROR(__xludf.DUMMYFUNCTION("""COMPUTED_VALUE"""),"Martin 3 sole size 39") -> Martin 3 sole size 39 | C20: =IFERROR(__xludf.DUMMYFUNCTION("""COMPUTED_VALUE"""),"Bali Rawat") -> Bali Rawat | D20: =IFERROR(__xludf.DUMMYFUNCTION("""COMPUTED_VALUE"""),"Nepalgunj, muktpur 12, haltpost najik") -> Nepalgunj, muktpur 12, haltpost najik | E20: =IFERROR(__xludf.DUMMYFUNCTION("""COMPUTED_VALUE"""),9.745506225E9) -> 9745506225 | F20: =IFERROR(__xludf.DUMMYFUNCTION("""COMPUTED_VALUE"""),600.0) -> 600 | G20: =IFERROR(__xludf.DUMMYFUNCTION("""COMPUTED_VALUE"""),1600.0) -> 1600 | H20: =IFERROR(__xludf.DUMMYFUNCTION("""COMPUTED_VALUE"""),213.0) -> 213 | I20: =IFERROR(__xludf.DUMMYFUNCTION("""COMPUTED_VALUE"""),"Delivered") -> Delivered | J20: =IFERROR(__xludf.DUMMYFUNCTION("""COMPUTED_VALUE"""),45889.45898148148) -> 45889.459
A21: =IFERROR(__xludf.DUMMYFUNCTION("""COMPUTED_VALUE"""),45888.17445601852) -> 45888.174 | B21: =IFERROR(__xludf.DUMMYFUNCTION("""COMPUTED_VALUE"""),"Martin single 42") -> Martin single 42 | C21: =IFERROR(__xludf.DUMMYFUNCTION("""COMPUTED_VALUE"""),"Shree krishna") -> Shree krishna | D21: =IFERROR(__xludf.DUMMYFUNCTION("""COMPUTED_VALUE"""),"Ghalate, bhaktapur") -> Ghalate, bhaktapur | E21: =IFERROR(__xludf.DUMMYFUNCTION("""COMPUTED_VALUE"""),9.765007077E9) -> 9765007077 | F21: =IFERROR(__xludf.DUMMYFUNCTION("""COMPUTED_VALUE"""),400.0) -> 400 | G21: =IFERROR(__xludf.DUMMYFUNCTION("""COMPUTED_VALUE"""),1300.0) -> 1300 | H21: =IFERROR(__xludf.DUMMYFUNCTION("""COMPUTED_VALUE"""),102.25) -> 102.25 | I21: =IFERROR(__xludf.DUMMYFUNCTION("""COMPUTED_VALUE"""),"Delivered") -> Delivered | J21: =IFERROR(__xludf.DUMMYFUNCTION("""COMPUTED_VALUE"""),45889.2105787037) -> 45889.211
A22: =IFERROR(__xludf.DUMMYFUNCTION("""COMPUTED_VALUE"""),45887.16681712963) -> 45887.167 | B22: =IFERROR(__xludf.DUMMYFUNCTION("""COMPUTED_VALUE"""),"Martin triple sole size 40") -> Martin triple sole size 40 | C22: =IFERROR(__xludf.DUMMYFUNCTION("""COMPUTED_VALUE"""),"Aashish Gautam") -> Aashish Gautam | D22: =IFERROR(__xludf.DUMMYFUNCTION("""COMPUTED_VALUE"""),"Baitadi, patan, metallic municipality 7, kanda bazzar") -> Baitadi, patan, metallic municipality 7, kanda bazzar | E22: =IFERROR(__xludf.DUMMYFUNCTION("""COMPUTED_VALUE"""),9.768483761E9) -> 9768483761 | F22: =IFERROR(__xludf.DUMMYFUNCTION("""COMPUTED_VALUE"""),650.0) -> 650 | G22: =IFERROR(__xludf.DUMMYFUNCTION("""COMPUTED_VALUE"""),1650.0) -> 1650 | H22: =IFERROR(__xludf.DUMMYFUNCTION("""COMPUTED_VALUE"""),143.13) -> 143.13 | I22: =IFERROR(__xludf.DUMMYFUNCTION("""COMPUTED_VALUE"""),"Delivered") -> Delivered | J22: =IFERROR(__xludf.DUMMYFUNCTION("""COMPUTED_VALUE"""),45891.40899305556) -> 45891.409
A23: =IFERROR(__xludf.DUMMYFUNCTION("""COMPUTED_VALUE"""),45887.16091435185) -> 45887.161 | B23: =IFERROR(__xludf.DUMMYFUNCTION("""COMPUTED_VALUE"""),"Martin 3 sole size 40") -> Martin 3 sole size 40 | C23: =IFERROR(__xludf.DUMMYFUNCTION("""COMPUTED_VALUE"""),"Prince Shrestha") -> Prince Shrestha | D23: =IFERROR(__xludf.DUMMYFUNCTION("""COMPUTED_VALUE"""),"Beni bazzar ") -> Beni bazzar | E23: =IFERROR(__xludf.DUMMYFUNCTION("""COMPUTED_VALUE"""),9.765610848E9) -> 9765610848 | F23: =IFERROR(__xludf.DUMMYFUNCTION("""COMPUTED_VALUE"""),650.0) -> 650 | G23: =IFERROR(__xludf.DUMMYFUNCTION("""COMPUTED_VALUE"""),1650.0) -> 1650 | H23: =IFERROR(__xludf.DUMMYFUNCTION("""COMPUTED_VALUE"""),183.13) -> 183.13 | I23: =IFERROR(__xludf.DUMMYFUNCTION("""COMPUTED_VALUE"""),"Delivered") -> Delivered | J23: =IFERROR(__xludf.DUMMYFUNCTION("""COMPUTED_VALUE"""),45891.24974537037) -> 45891.25
A24: =IFERROR(__xludf.DUMMYFUNCTION("""COMPUTED_VALUE"""),45886.18208333333) -> 45886.182 | B24: =IFERROR(__xludf.DUMMYFUNCTION("""COMPUTED_VALUE"""),"Nike 40 Black white ") -> Nike 40 Black white | C24: =IFERROR(__xludf.DUMMYFUNCTION("""COMPUTED_VALUE"""),"Siddhartha Gautam") -> Siddhartha Gautam | D24: =IFERROR(__xludf.DUMMYFUNCTION("""COMPUTED_VALUE"""),"Kathmandu,Balkot big mart, Brihaspati marga") -> Kathmandu,Balkot big mart, Brihaspati marga | E24: =IFERROR(__xludf.DUMMYFUNCTION("""COMPUTED_VALUE"""),9.862541342E9) -> 9862541342 | F24: =IFERROR(__xludf.DUMMYFUNCTION("""COMPUTED_VALUE"""),300.0) -> 300 | G24: =IFERROR(__xludf.DUMMYFUNCTION("""COMPUTED_VALUE"""),1300.0) -> 1300 | H24: =IFERROR(__xludf.DUMMYFUNCTION("""COMPUTED_VALUE"""),3.25) -> 3.25 | I24: =IFERROR(__xludf.DUMMYFUNCTION("""COMPUTED_VALUE"""),"Delivered") -> Delivered | J24: =IFERROR(__xludf.DUMMYFUNCTION("""COMPUTED_VALUE"""),45886.49072916667) -> 45886.491
A25: =IFERROR(__xludf.DUMMYFUNCTION("""COMPUTED_VALUE"""),45873.199583333335) -> 45873.2 | B25: =IFERROR(__xludf.DUMMYFUNCTION("""COMPUTED_VALUE"""),"Martin naysbasti 3 sole 41") -> Martin naysbasti 3 sole 41 | C25: =IFERROR(__xludf.DUMMYFUNCTION("""COMPUTED_VALUE"""),"Santosh") -> Santosh | D25: =IFERROR(__xludf.DUMMYFUNCTION("""COMPUTED_VALUE"""),"Dang, ghorahi") -> Dang, ghorahi | E25: =IFERROR(__xludf.DUMMYFUNCTION("""COMPUTED_VALUE"""),9.818118588E9) -> 9818118588 | F25: =IFERROR(__xludf.DUMMYFUNCTION("""COMPUTED_VALUE"""),550.0) -> 550 | G25: =IFERROR(__xludf.DUMMYFUNCTION("""COMPUTED_VALUE"""),1550.0) -> 1550 | H25: =IFERROR(__xludf.DUMMYFUNCTION("""COMPUTED_VALUE"""),182.88) -> 182.88 | I25: =IFERROR(__xludf.DUMMYFUNCTION("""COMPUTED_VALUE"""),"Delivered") -> Delivered | J25: =IFERROR(__xludf.DUMMYFUNCTION("""COMPUTED_VALUE"""),45882.43194444444) -> 45882.432
A26: =IFERROR(__xludf.DUMMYFUNCTION("""COMPUTED_VALUE"""),45873.19865740741) -> 45873.199 | B26: =IFERROR(__xludf.DUMMYFUNCTION("""COMPUTED_VALUE"""),"Martin half 2 sole 39") -> Martin half 2 sole 39 | C26: =IFERROR(__xludf.DUMMYFUNCTION("""COMPUTED_VALUE"""),"Sudip Darnal") -> Sudip Darnal | D26: =IFERROR(__xludf.DUMMYFUNCTION("""COMPUTED_VALUE"""),"Sangwale ward 4, sindhuli") -> Sangwale ward 4, sindhuli | E26: =IFERROR(__xludf.DUMMYFUNCTION("""COMPUTED_VALUE"""),9.766529083E9) -> 9766529083 | F26: =IFERROR(__xludf.DUMMYFUNCTION("""COMPUTED_VALUE"""),350.0) -> 350 | G26: =IFERROR(__xludf.DUMMYFUNCTION("""COMPUTED_VALUE"""),1350.0) -> 1350 | H26: =IFERROR(__xludf.DUMMYFUNCTION("""COMPUTED_VALUE"""),162.38) -> 162.38 | I26: =IFERROR(__xludf.DUMMYFUNCTION("""COMPUTED_VALUE"""),"Delivered") -> Delivered | J26: =IFERROR(__xludf.DUMMYFUNCTION("""COMPUTED_VALUE"""),45877.46166666667) -> 45877.462
A27: =IFERROR(__xludf.DUMMYFUNCTION("""COMPUTED_VALUE"""),45872.17322916667) -> 45872.173 | B27: =IFERROR(__xludf.DUMMYFUNCTION("""COMPUTED_VALUE"""),"Sr smile 41") -> Sr smile 41 | C27: =IFERROR(__xludf.DUMMYFUNCTION("""COMPUTED_VALUE"""),"Bibash Thapa") -> Bibash Thapa | D27: =IFERROR(__xludf.DUMMYFUNCTION("""COMPUTED_VALUE"""),"Gulariya 6, bardiya") -> Gulariya 6, bardiya | E27: =IFERROR(__xludf.DUMMYFUNCTION("""COMPUTED_VALUE"""),9.816523777E9) -> 9816523777 | F27: =IFERROR(__xludf.DUMMYFUNCTION("""COMPUTED_VALUE"""),450.0) -> 450 | G27: =IFERROR(__xludf.DUMMYFUNCTION("""COMPUTED_VALUE"""),1450.0) -> 1450 | H27: =IFERROR(__xludf.DUMMYFUNCTION("""COMPUTED_VALUE"""),182.63) -> 182.63 | I27: =IFERROR(__xludf.DUMMYFUNCTION("""COMPUTED_VALUE"""),"Delivered") -> Delivered | J27: =IFERROR(__xludf.DUMMYFUNCTION("""COMPUTED_VALUE"""),45873.35476851852) -> 45873.355
A28: =IFERROR(__xludf.DUMMYFUNCTION("""COMPUTED_VALUE"""),45872.17152777778) -> 45872.172 | B28: =IFERROR(__xludf.DUMMYFUNCTION("""COMPUTED_VALUE"""),"Martin nayabasti factory 40") -> Martin nayabasti factory 40 | C28: =IFERROR(__xludf.DUMMYFUNCTION("""COMPUTED_VALUE"""),"Nischal Tamang") -> Nischal Tamang | D28: =IFERROR(__xludf.DUMMYFUNCTION("""COMPUTED_VALUE"""),"Dingla, bhojpur") -> Dingla, bhojpur | E28: =IFERROR(__xludf.DUMMYFUNCTION("""COMPUTED_VALUE"""),9.820330404E9) -> 9820330404 | F28: =IFERROR(__xludf.DUMMYFUNCTION("""COMPUTED_VALUE"""),550.0) -> 550 | G28: =IFERROR(__xludf.DUMMYFUNCTION("""COMPUTED_VALUE"""),1550.0) -> 1550 | H28: =IFERROR(__xludf.DUMMYFUNCTION("""COMPUTED_VALUE"""),212.88) -> 212.88 | I28: =IFERROR(__xludf.DUMMYFUNCTION("""COMPUTED_VALUE"""),"Delivered") -> Delivered | J28: =IFERROR(__xludf.DUMMYFUNCTION("""COMPUTED_VALUE"""),45875.59798611111) -> 45875.598
A29: =IFERROR(__xludf.DUMMYFUNCTION("""COMPUTED_VALUE"""),45872.17049768519) -> 45872.171 | B29: =IFERROR(__xludf.DUMMYFUNCTION("""COMPUTED_VALUE"""),"Martin single sole 42") -> Martin single sole 42 | C29: =IFERROR(__xludf.DUMMYFUNCTION("""COMPUTED_VALUE"""),"Rohan Bam") -> Rohan Bam | D29: =IFERROR(__xludf.DUMMYFUNCTION("""COMPUTED_VALUE"""),"Bardageriya gaupalika, ward no 2, kumbiya, kailali") -> Bardageriya gaupalika, ward no 2, kumbiya, kailali | E29: =IFERROR(__xludf.DUMMYFUNCTION("""COMPUTED_VALUE"""),9.815663088E9) -> 9815663088 | F29: =IFERROR(__xludf.DUMMYFUNCTION("""COMPUTED_VALUE"""),350.0) -> 350 | G29: =IFERROR(__xludf.DUMMYFUNCTION("""COMPUTED_VALUE"""),1350.0) -> 1350 | H29: =IFERROR(__xludf.DUMMYFUNCTION("""COMPUTED_VALUE"""),182.38) -> 182.38 | I29: =IFERROR(__xludf.DUMMYFUNCTION("""COMPUTED_VALUE"""),"Delivered") -> Delivered | J29: =IFERROR(__xludf.DUMMYFUNCTION("""COMPUTED_VALUE"""),45877.282442129625) -> 45877.282
A30: =IFERROR(__xludf.DUMMYFUNCTION("""COMPUTED_VALUE"""),45869.2041087963) -> 45869.204 | B30: =IFERROR(__xludf.DUMMYFUNCTION("""COMPUTED_VALUE"""),"Martin single sole 41") -> Martin single sole 41 | C30: =IFERROR(__xludf.DUMMYFUNCTION("""COMPUTED_VALUE"""),"Santosh Pariyar") -> Santosh Pariyar | D30: =IFERROR(__xludf.DUMMYFUNCTION("""COMPUTED_VALUE"""),"Gogli chowk, dang") -> Gogli chowk, dang | E30: =IFERROR(__xludf.DUMMYFUNCTION("""COMPUTED_VALUE"""),9.706877325E9) -> 9706877325 | F30: =IFERROR(__xludf.DUMMYFUNCTION("""COMPUTED_VALUE"""),350.0) -> 350 | G30: =IFERROR(__xludf.DUMMYFUNCTION("""COMPUTED_VALUE"""),1350.0) -> 1350 | H30: =IFERROR(__xludf.DUMMYFUNCTION("""COMPUTED_VALUE"""),182.38) -> 182.38 | I30: =IFERROR(__xludf.DUMMYFUNCTION("""COMPUTED_VALUE"""),"Delivered") -> Delivered | J30: =IFERROR(__xludf.DUMMYFUNCTION("""COMPUTED_VALUE"""),45872.361342592594) -> 45872.361
A31: =IFERROR(__xludf.DUMMYFUNCTION("""COMPUTED_VALUE"""),45869.20298611111) -> 45869.203 | B31: =IFERROR(__xludf.DUMMYFUNCTION("""COMPUTED_VALUE"""),"Sr gray 42") -> Sr gray 42 | C31: =IFERROR(__xludf.DUMMYFUNCTION("""COMPUTED_VALUE"""),"Subarth Kunwar") -> Subarth Kunwar | D31: =IFERROR(__xludf.DUMMYFUNCTION("""COMPUTED_VALUE"""),"Baneshwor soa and swimming pool or ananda events and meeting") -> Baneshwor soa and swimming pool or ananda events and meeting | E31: =IFERROR(__xludf.DUMMYFUNCTION("""COMPUTED_VALUE"""),9.763313182E9) -> 9763313182 | F31: =IFERROR(__xludf.DUMMYFUNCTION("""COMPUTED_VALUE"""),400.0) -> 400 | G31: =IFERROR(__xludf.DUMMYFUNCTION("""COMPUTED_VALUE"""),1400.0) -> 1400 | H31: =IFERROR(__xludf.DUMMYFUNCTION("""COMPUTED_VALUE"""),102.5) -> 102.5 | I31: =IFERROR(__xludf.DUMMYFUNCTION("""COMPUTED_VALUE"""),"Delivered") -> Delivered | J31: =IFERROR(__xludf.DUMMYFUNCTION("""COMPUTED_VALUE"""),45869.45903935185) -> 45869.459
A32: =IFERROR(__xludf.DUMMYFUNCTION("""COMPUTED_VALUE"""),45867.21146990741) -> 45867.211 | B32: =IFERROR(__xludf.DUMMYFUNCTION("""COMPUTED_VALUE"""),"Nie 11 red and black") -> Nie 11 red and black | C32: =IFERROR(__xludf.DUMMYFUNCTION("""COMPUTED_VALUE"""),"Raj Thegim Limbu") -> Raj Thegim Limbu | D32: =IFERROR(__xludf.DUMMYFUNCTION("""COMPUTED_VALUE"""),"Jalthal, jhapa") -> Jalthal, jhapa | E32: =IFERROR(__xludf.DUMMYFUNCTION("""COMPUTED_VALUE"""),9.814977789E9) -> 9814977789 | F32: =IFERROR(__xludf.DUMMYFUNCTION("""COMPUTED_VALUE"""),700.0) -> 700 | G32: =IFERROR(__xludf.DUMMYFUNCTION("""COMPUTED_VALUE"""),2500.0) -> 2500 | H32: =IFERROR(__xludf.DUMMYFUNCTION("""COMPUTED_VALUE"""),185.25) -> 185.25 | I32: =IFERROR(__xludf.DUMMYFUNCTION("""COMPUTED_VALUE"""),"Delivered") -> Delivered | J32: =IFERROR(__xludf.DUMMYFUNCTION("""COMPUTED_VALUE"""),45870.19578703704) -> 45870.196
A33: =IFERROR(__xludf.DUMMYFUNCTION("""COMPUTED_VALUE"""),45867.20958333333) -> 45867.21 | B33: =IFERROR(__xludf.DUMMYFUNCTION("""COMPUTED_VALUE"""),"White Nike 37") -> White Nike 37 | C33: =IFERROR(__xludf.DUMMYFUNCTION("""COMPUTED_VALUE"""),"Gaurav Jaiswal") -> Gaurav Jaiswal | D33: =IFERROR(__xludf.DUMMYFUNCTION("""COMPUTED_VALUE"""),"Nepalgunj, dhamboji chowk siddhartha Bank najik") -> Nepalgunj, dhamboji chowk siddhartha Bank najik | E33: =IFERROR(__xludf.DUMMYFUNCTION("""COMPUTED_VALUE"""),9.762065388E9) -> 9762065388 | F33: =IFERROR(__xludf.DUMMYFUNCTION("""COMPUTED_VALUE"""),350.0) -> 350 | G33: =IFERROR(__xludf.DUMMYFUNCTION("""COMPUTED_VALUE"""),1350.0) -> 1350 | H33: =IFERROR(__xludf.DUMMYFUNCTION("""COMPUTED_VALUE"""),212.38) -> 212.38 | I33: =IFERROR(__xludf.DUMMYFUNCTION("""COMPUTED_VALUE"""),"Delivered") -> Delivered | J33: =IFERROR(__xludf.DUMMYFUNCTION("""COMPUTED_VALUE"""),45872.44072916667) -> 45872.441
A34: =IFERROR(__xludf.DUMMYFUNCTION("""COMPUTED_VALUE"""),45865.19533564815) -> 45865.195 | B34: =IFERROR(__xludf.DUMMYFUNCTION("""COMPUTED_VALUE"""),"Martin 3 sole size 39") -> Martin 3 sole size 39 | C34: =IFERROR(__xludf.DUMMYFUNCTION("""COMPUTED_VALUE"""),"Manoj") -> Manoj | D34: =IFERROR(__xludf.DUMMYFUNCTION("""COMPUTED_VALUE"""),"Ktm, sundarijal dobato chowk") -> Ktm, sundarijal dobato chowk | E34: =IFERROR(__xludf.DUMMYFUNCTION("""COMPUTED_VALUE"""),9.768966994E9) -> 9768966994 | F34: =IFERROR(__xludf.DUMMYFUNCTION("""COMPUTED_VALUE"""),500.0) -> 500 | G34: =IFERROR(__xludf.DUMMYFUNCTION("""COMPUTED_VALUE"""),1500.0) -> 1500 | H34: =IFERROR(__xludf.DUMMYFUNCTION("""COMPUTED_VALUE"""),102.75) -> 102.75 | I34: =IFERROR(__xludf.DUMMYFUNCTION("""COMPUTED_VALUE"""),"Delivered") -> Delivered | J34: =IFERROR(__xludf.DUMMYFUNCTION("""COMPUTED_VALUE"""),45867.2159837963) -> 45867.216
A35: =IFERROR(__xludf.DUMMYFUNCTION("""COMPUTED_VALUE"""),45865.183171296296) -> 45865.183 | B35: =IFERROR(__xludf.DUMMYFUNCTION("""COMPUTED_VALUE"""),"Chelsea size 41") -> Chelsea size 41 | C35: =IFERROR(__xludf.DUMMYFUNCTION("""COMPUTED_VALUE"""),"Sudesh Shrestha") -> Sudesh Shrestha | D35: =IFERROR(__xludf.DUMMYFUNCTION("""COMPUTED_VALUE"""),"Sundar haraicha 12, biratchowk Road no 12") -> Sundar haraicha 12, biratchowk Road no 12 | E35: =IFERROR(__xludf.DUMMYFUNCTION("""COMPUTED_VALUE"""),9.862232928E9) -> 9862232928 | F35: =IFERROR(__xludf.DUMMYFUNCTION("""COMPUTED_VALUE"""),450.0) -> 450 | G35: =IFERROR(__xludf.DUMMYFUNCTION("""COMPUTED_VALUE"""),1350.0) -> 1350 | H35: =IFERROR(__xludf.DUMMYFUNCTION("""COMPUTED_VALUE"""),162.38) -> 162.38 | I35: =IFERROR(__xludf.DUMMYFUNCTION("""COMPUTED_VALUE"""),"Delivered") -> Delivered | J35: =IFERROR(__xludf.DUMMYFUNCTION("""COMPUTED_VALUE"""),45867.38013888889) -> 45867.38
A36: =IFERROR(__xludf.DUMMYFUNCTION("""COMPUTED_VALUE"""),45865.18116898148) -> 45865.181 | B36: =IFERROR(__xludf.DUMMYFUNCTION("""COMPUTED_VALUE"""),"Sb dunk 41") -> Sb dunk 41 | C36: =IFERROR(__xludf.DUMMYFUNCTION("""COMPUTED_VALUE"""),"Sijan Shrestha") -> Sijan Shrestha | D36: =IFERROR(__xludf.DUMMYFUNCTION("""COMPUTED_VALUE"""),"Beni, myagdi") -> Beni, myagdi | E36: =IFERROR(__xludf.DUMMYFUNCTION("""COMPUTED_VALUE"""),9.84764997E9) -> 9847649970 | F36: =IFERROR(__xludf.DUMMYFUNCTION("""COMPUTED_VALUE"""),400.0) -> 400 | G36: =IFERROR(__xludf.DUMMYFUNCTION("""COMPUTED_VALUE"""),1400.0) -> 1400 | H36: =IFERROR(__xludf.DUMMYFUNCTION("""COMPUTED_VALUE"""),212.5) -> 212.5 | I36: =IFERROR(__xludf.DUMMYFUNCTION("""COMPUTED_VALUE"""),"Delivered") -> Delivered | J36: =IFERROR(__xludf.DUMMYFUNCTION("""COMPUTED_VALUE"""),45867.280752314815) -> 45867.281
A37: =IFERROR(__xludf.DUMMYFUNCTION("""COMPUTED_VALUE"""),45865.17979166667) -> 45865.18 | B37: =IFERROR(__xludf.DUMMYFUNCTION("""COMPUTED_VALUE"""),"Red Nike ") -> Red Nike | C37: =IFERROR(__xludf.DUMMYFUNCTION("""COMPUTED_VALUE"""),"Aayush Panthi") -> Aayush Panthi | D37: =IFERROR(__xludf.DUMMYFUNCTION("""COMPUTED_VALUE"""),"Butwal, bhakwari 7, lec college side") -> Butwal, bhakwari 7, lec college side | E37: =IFERROR(__xludf.DUMMYFUNCTION("""COMPUTED_VALUE"""),9.844755593E9) -> 9844755593 | F37: =IFERROR(__xludf.DUMMYFUNCTION("""COMPUTED_VALUE"""),350.0) -> 350 | G37: =IFERROR(__xludf.DUMMYFUNCTION("""COMPUTED_VALUE"""),1350.0) -> 1350 | H37: =IFERROR(__xludf.DUMMYFUNCTION("""COMPUTED_VALUE"""),182.38) -> 182.38 | I37: =IFERROR(__xludf.DUMMYFUNCTION("""COMPUTED_VALUE"""),"Delivered") -> Delivered | J37: =IFERROR(__xludf.DUMMYFUNCTION("""COMPUTED_VALUE"""),45866.38072916667) -> 45866.381
A38: =IFERROR(__xludf.DUMMYFUNCTION("""COMPUTED_VALUE"""),45865.17822916667) -> 45865.178 | B38: =IFERROR(__xludf.DUMMYFUNCTION("""COMPUTED_VALUE"""),"Dark brown 40") -> Dark brown 40 | C38: =IFERROR(__xludf.DUMMYFUNCTION("""COMPUTED_VALUE"""),"Govinda Khatiwada") -> Govinda Khatiwada | D38: =IFERROR(__xludf.DUMMYFUNCTION("""COMPUTED_VALUE"""),"Salleri bazar, solukhumbu") -> Salleri bazar, solukhumbu | E38: =IFERROR(__xludf.DUMMYFUNCTION("""COMPUTED_VALUE"""),9.869667233E9) -> 9869667233 | F38: =IFERROR(__xludf.DUMMYFUNCTION("""COMPUTED_VALUE"""),320.0) -> 320 | G38: =IFERROR(__xludf.DUMMYFUNCTION("""COMPUTED_VALUE"""),1320.0) -> 1320 | H38: =IFERROR(__xludf.DUMMYFUNCTION("""COMPUTED_VALUE"""),212.3) -> 212.3 | I38: =IFERROR(__xludf.DUMMYFUNCTION("""COMPUTED_VALUE"""),"Delivered") -> Delivered | J38: =IFERROR(__xludf.DUMMYFUNCTION("""COMPUTED_VALUE"""),45867.60194444444) -> 45867.602
A39: =IFERROR(__xludf.DUMMYFUNCTION("""COMPUTED_VALUE"""),45864.20482638889) -> 45864.205 | B39: =IFERROR(__xludf.DUMMYFUNCTION("""COMPUTED_VALUE"""),"Size 39 Martin 3 sole") -> Size 39 Martin 3 sole | C39: =IFERROR(__xludf.DUMMYFUNCTION("""COMPUTED_VALUE"""),"Rohan") -> Rohan | D39: =IFERROR(__xludf.DUMMYFUNCTION("""COMPUTED_VALUE"""),"Manakamana suit hotel, gogechaur, banepa") -> Manakamana suit hotel, gogechaur, banepa | E39: =IFERROR(__xludf.DUMMYFUNCTION("""COMPUTED_VALUE"""),9.701538165E9) -> 9701538165 | F39: =IFERROR(__xludf.DUMMYFUNCTION("""COMPUTED_VALUE"""),600.0) -> 600 | G39: =IFERROR(__xludf.DUMMYFUNCTION("""COMPUTED_VALUE"""),1600.0) -> 1600 | H39: =IFERROR(__xludf.DUMMYFUNCTION("""COMPUTED_VALUE"""),163.0) -> 163 | I39: =IFERROR(__xludf.DUMMYFUNCTION("""COMPUTED_VALUE"""),"Delivered") -> Delivered | J39: =IFERROR(__xludf.DUMMYFUNCTION("""COMPUTED_VALUE"""),45865.5271875) -> 45865.527
A40: =IFERROR(__xludf.DUMMYFUNCTION("""COMPUTED_VALUE"""),45864.203668981485) -> 45864.204 | B40: =IFERROR(__xludf.DUMMYFUNCTION("""COMPUTED_VALUE"""),"Single sole Martin 43") -> Single sole Martin 43 | C40: =IFERROR(__xludf.DUMMYFUNCTION("""COMPUTED_VALUE"""),"Ankit Rajbanshi") -> Ankit Rajbanshi | D40: =IFERROR(__xludf.DUMMYFUNCTION("""COMPUTED_VALUE"""),"Mechinagar-10, dhulabari, jhapa") -> Mechinagar-10, dhulabari, jhapa | E40: =IFERROR(__xludf.DUMMYFUNCTION("""COMPUTED_VALUE"""),9.827940827E9) -> 9827940827 | F40: =IFERROR(__xludf.DUMMYFUNCTION("""COMPUTED_VALUE"""),350.0) -> 350 | G40: =IFERROR(__xludf.DUMMYFUNCTION("""COMPUTED_VALUE"""),1350.0) -> 1350 | H40: =IFERROR(__xludf.DUMMYFUNCTION("""COMPUTED_VALUE"""),182.38) -> 182.38 | I40: =IFERROR(__xludf.DUMMYFUNCTION("""COMPUTED_VALUE"""),"Delivered") -> Delivered | J40: =IFERROR(__xludf.DUMMYFUNCTION("""COMPUTED_VALUE"""),45866.45042824074) -> 45866.45
...

Sheet delievered
B2: =IFERROR(__xludf.DUMMYFUNCTION("QUERY(reference!A1:J188, ""where I = 'Delivered'"", 1)"),"Order created at") -> Order created at | C2: =IFERROR(__xludf.DUMMYFUNCTION("""COMPUTED_VALUE"""),"Order description") -> Order description | D2: =IFERROR(__xludf.DUMMYFUNCTION("""COMPUTED_VALUE"""),"Recipient name") -> Recipient name | E2: =IFERROR(__xludf.DUMMYFUNCTION("""COMPUTED_VALUE"""),"Recipient address") -> Recipient address | F2: =IFERROR(__xludf.DUMMYFUNCTION("""COMPUTED_VALUE"""),"Recipient phone") -> Recipient phone | G2: =IFERROR(__xludf.DUMMYFUNCTION("""COMPUTED_VALUE"""),"proft") -> proft | H2: =IFERROR(__xludf.DUMMYFUNCTION("""COMPUTED_VALUE"""),"Collected amount") -> Collected amount | I2: =IFERROR(__xludf.DUMMYFUNCTION("""COMPUTED_VALUE"""),"Total fee") -> Total fee | J2: =IFERROR(__xludf.DUMMYFUNCTION("""COMPUTED_VALUE"""),"Order status") -> Order status | K2: =IFERROR(__xludf.DUMMYFUNCTION("""COMPUTED_VALUE"""),"Order status") -> Order status | L2: Tierwise | M2: Province
B3: =IFERROR(__xludf.DUMMYFUNCTION("""COMPUTED_VALUE"""),45916.191412037035) -> 45916.191 | C3: =IFERROR(__xludf.DUMMYFUNCTION("""COMPUTED_VALUE"""),"Martin 2 sole half ") -> Martin 2 sole half | D3: =IFERROR(__xludf.DUMMYFUNCTION("""COMPUTED_VALUE"""),"Amit Magar") -> Amit Magar | E3: =IFERROR(__xludf.DUMMYFUNCTION("""COMPUTED_VALUE"""),"Dharan, bhanu chowk ") -> Dharan, bhanu chowk | F3: =IFERROR(__xludf.DUMMYFUNCTION("""COMPUTED_VALUE"""),9.84940118E9) -> 9849401180 | G3: =IFERROR(__xludf.DUMMYFUNCTION("""COMPUTED_VALUE"""),350.0) -> 350 | H3: =IFERROR(__xludf.DUMMYFUNCTION("""COMPUTED_VALUE"""),1350.0) -> 1350 | I3: =IFERROR(__xludf.DUMMYFUNCTION("""COMPUTED_VALUE"""),162.38) -> 162.38 | J3: =IFERROR(__xludf.DUMMYFUNCTION("""COMPUTED_VALUE"""),"Delivered") -> Delivered | K3: =IFERROR(__xludf.DUMMYFUNCTION("""COMPUTED_VALUE"""),45918.31509259259) -> 45918.315 | L3: =IFERROR(__xludf.DUMMYFUNCTION("IFS( OR(REGEXMATCH(LOWER(E3), ""sirutar|sundarijal|sitapaila|duwakot|tikathali|bhaktapur|lalitpur|kathmandu|ktm|changunarayan|bageswari|ghalate|tinkune|balkot|tikathali""), REGEXMATCH(LOWER(E3), ""inside valley"")), ""Inside Valley"", REGEXMATCH(LOWER"&"(E3), ""dharan|pokhara|biratnagar|birgunj|narayanghat|itahari|hetauda|janakpur|madi""), ""Tier 1"", REGEXMATCH(LOWER(E3), ""nepalgunj|butwal|birtamod|dhangadhi|ghorahi|beni|kushma|waling|haldibari|dulegauda|baitadi|bhadrapur|syangja|parbat|myagdi|dang|n"&"uwakot|jhapa""), ""Tier 2"", TRUE, ""Tier 3"" )"),"Tier 1") -> Tier 1 | M3: Koshi
B4: =IFERROR(__xludf.DUMMYFUNCTION("""COMPUTED_VALUE"""),45916.18975694444) -> 45916.19 | C4: =IFERROR(__xludf.DUMMYFUNCTION("""COMPUTED_VALUE"""),"N and red 37 and 40") -> N and red 37 and 40 | D4: =IFERROR(__xludf.DUMMYFUNCTION("""COMPUTED_VALUE"""),"Prabin karki") -> Prabin karki | E4: =IFERROR(__xludf.DUMMYFUNCTION("""COMPUTED_VALUE"""),"Solukhumbu tingla") -> Solukhumbu tingla | F4: =IFERROR(__xludf.DUMMYFUNCTION("""COMPUTED_VALUE"""),9.749215487E9) -> 9749215487 | G4: =IFERROR(__xludf.DUMMYFUNCTION("""COMPUTED_VALUE"""),450.0) -> 450 | H4: =IFERROR(__xludf.DUMMYFUNCTION("""COMPUTED_VALUE"""),2550.0) -> 2550 | I4: =IFERROR(__xludf.DUMMYFUNCTION("""COMPUTED_VALUE"""),215.38) -> 215.38 | J4: =IFERROR(__xludf.DUMMYFUNCTION("""COMPUTED_VALUE"""),"Delivered") -> Delivered | K4: =IFERROR(__xludf.DUMMYFUNCTION("""COMPUTED_VALUE"""),45919.61679398148) -> 45919.617 | L4: =IFERROR(__xludf.DUMMYFUNCTION("IFS( OR(REGEXMATCH(LOWER(E4), ""sirutar|sundarijal|sitapaila|duwakot|tikathali|bhaktapur|lalitpur|kathmandu|ktm|changunarayan|bageswari|ghalate|tinkune|balkot|tikathali""), REGEXMATCH(LOWER(E4), ""inside valley"")), ""Inside Valley"", REGEXMATCH(LOWER"&"(E4), ""dharan|pokhara|biratnagar|birgunj|narayanghat|itahari|hetauda|janakpur|madi""), ""Tier 1"", REGEXMATCH(LOWER(E4), ""nepalgunj|butwal|birtamod|dhangadhi|ghorahi|beni|kushma|waling|haldibari|dulegauda|baitadi|bhadrapur|syangja|parbat|myagdi|dang|n"&"uwakot|jhapa""), ""Tier 2"", TRUE, ""Tier 3"" )"),"Tier 3") -> Tier 3 | M4: Koshi | N4: Province | O4: Tier 1 | P4: Tier 2 | Q4: Tier 3 | R4: Total
B5: =IFERROR(__xludf.DUMMYFUNCTION("""COMPUTED_VALUE"""),45894.19651620371) -> 45894.197 | C5: =IFERROR(__xludf.DUMMYFUNCTION("""COMPUTED_VALUE"""),"Martin 1 sole 36") -> Martin 1 sole 36 | D5: =IFERROR(__xludf.DUMMYFUNCTION("""COMPUTED_VALUE"""),"Manoj") -> Manoj | E5: =IFERROR(__xludf.DUMMYFUNCTION("""COMPUTED_VALUE"""),"Sundarijal, ktm dobato chowk") -> Sundarijal, ktm dobato chowk | F5: =IFERROR(__xludf.DUMMYFUNCTION("""COMPUTED_VALUE"""),9.768966994E9) -> 9768966994 | G5: =IFERROR(__xludf.DUMMYFUNCTION("""COMPUTED_VALUE"""),300.0) -> 300 | H5: =IFERROR(__xludf.DUMMYFUNCTION("""COMPUTED_VALUE"""),1100.0) -> 1100 | I5: =IFERROR(__xludf.DUMMYFUNCTION("""COMPUTED_VALUE"""),101.75) -> 101.75 | J5: =IFERROR(__xludf.DUMMYFUNCTION("""COMPUTED_VALUE"""),"Delivered") -> Delivered | K5: =IFERROR(__xludf.DUMMYFUNCTION("""COMPUTED_VALUE"""),45894.44189814814) -> 45894.442 | L5: =IFERROR(__xludf.DUMMYFUNCTION("IFS( OR(REGEXMATCH(LOWER(E5), ""sirutar|sundarijal|sitapaila|duwakot|tikathali|bhaktapur|lalitpur|kathmandu|ktm|changunarayan|bageswari|ghalate|tinkune|balkot|tikathali""), REGEXMATCH(LOWER(E5), ""inside valley"")), ""Inside Valley"", REGEXMATCH(LOWER"&"(E5), ""dharan|pokhara|biratnagar|birgunj|narayanghat|itahari|hetauda|janakpur|madi""), ""Tier 1"", REGEXMATCH(LOWER(E5), ""nepalgunj|butwal|birtamod|dhangadhi|ghorahi|beni|kushma|waling|haldibari|dulegauda|baitadi|bhadrapur|syangja|parbat|myagdi|dang|n"&"uwakot|jhapa""), ""Tier 2"", TRUE, ""Tier 3"" )"),"Inside Valley") -> Inside Valley | M5: Bagmati | N5: **Bagmati** | O5: 24 | P5: 2 | Q5: 17 | R5: **43**
B6: =IFERROR(__xludf.DUMMYFUNCTION("""COMPUTED_VALUE"""),45893.18133101852) -> 45893.181 | C6: =IFERROR(__xludf.DUMMYFUNCTION("""COMPUTED_VALUE"""),"Martin 3 sole 41") -> Martin 3 sole 41 | D6: =IFERROR(__xludf.DUMMYFUNCTION("""COMPUTED_VALUE"""),"Manish Bishwokarma") -> Manish Bishwokarma | E6: =IFERROR(__xludf.DUMMYFUNCTION("""COMPUTED_VALUE"""),"Tanahun, dulegauda ") -> Tanahun, dulegauda | F6: =IFERROR(__xludf.DUMMYFUNCTION("""COMPUTED_VALUE"""),9.815193182E9) -> 9815193182 | G6: =IFERROR(__xludf.DUMMYFUNCTION("""COMPUTED_VALUE"""),650.0) -> 650 | H6: =IFERROR(__xludf.DUMMYFUNCTION("""COMPUTED_VALUE"""),1650.0) -> 1650 | I6: =IFERROR(__xludf.DUMMYFUNCTION("""COMPUTED_VALUE"""),183.13) -> 183.13 | J6: =IFERROR(__xludf.DUMMYFUNCTION("""COMPUTED_VALUE"""),"Delivered") -> Delivered | K6: =IFERROR(__xludf.DUMMYFUNCTION("""COMPUTED_VALUE"""),45894.3146412037) -> 45894.315 | L6: =IFERROR(__xludf.DUMMYFUNCTION("IFS( OR(REGEXMATCH(LOWER(E6), ""sirutar|sundarijal|sitapaila|duwakot|tikathali|bhaktapur|lalitpur|kathmandu|ktm|changunarayan|bageswari|ghalate|tinkune|balkot|tikathali""), REGEXMATCH(LOWER(E6), ""inside valley"")), ""Inside Valley"", REGEXMATCH(LOWER"&"(E6), ""dharan|pokhara|biratnagar|birgunj|narayanghat|itahari|hetauda|janakpur|madi""), ""Tier 1"", REGEXMATCH(LOWER(E6), ""nepalgunj|butwal|birtamod|dhangadhi|ghorahi|beni|kushma|waling|haldibari|dulegauda|baitadi|bhadrapur|syangja|parbat|myagdi|dang|n"&"uwakot|jhapa""), ""Tier 2"", TRUE, ""Tier 3"" )"),"Tier 2") -> Tier 2 | M6: Gandaki | N6: **Koshi** | O6: 6 | P6: 8 | Q6: 19 | R6: **33**
B7: =IFERROR(__xludf.DUMMYFUNCTION("""COMPUTED_VALUE"""),45893.17900462963) -> 45893.179 | C7: =IFERROR(__xludf.DUMMYFUNCTION("""COMPUTED_VALUE"""),"Blue Nike 39") -> Blue Nike 39 | D7: =IFERROR(__xludf.DUMMYFUNCTION("""COMPUTED_VALUE"""),"Rajdip Chudal") -> Rajdip Chudal | E7: =IFERROR(__xludf.DUMMYFUNCTION("""COMPUTED_VALUE"""),"Haldibari 4, magalbare jhapa") -> Haldibari 4, magalbare jhapa | F7: =IFERROR(__xludf.DUMMYFUNCTION("""COMPUTED_VALUE"""),9.815936372E9) -> 9815936372 | G7: =IFERROR(__xludf.DUMMYFUNCTION("""COMPUTED_VALUE"""),350.0) -> 350 | H7: =IFERROR(__xludf.DUMMYFUNCTION("""COMPUTED_VALUE"""),1350.0) -> 1350 | I7: =IFERROR(__xludf.DUMMYFUNCTION("""COMPUTED_VALUE"""),182.38) -> 182.38 | J7: =IFERROR(__xludf.DUMMYFUNCTION("""COMPUTED_VALUE"""),"Delivered") -> Delivered | K7: =IFERROR(__xludf.DUMMYFUNCTION("""COMPUTED_VALUE"""),45895.44592592593) -> 45895.446 | L7: =IFERROR(__xludf.DUMMYFUNCTION("IFS( OR(REGEXMATCH(LOWER(E7), ""sirutar|sundarijal|sitapaila|duwakot|tikathali|bhaktapur|lalitpur|kathmandu|ktm|changunarayan|bageswari|ghalate|tinkune|balkot|tikathali""), REGEXMATCH(LOWER(E7), ""inside valley"")), ""Inside Valley"", REGEXMATCH(LOWER"&"(E7), ""dharan|pokhara|biratnagar|birgunj|narayanghat|itahari|hetauda|janakpur|madi""), ""Tier 1"", REGEXMATCH(LOWER(E7), ""nepalgunj|butwal|birtamod|dhangadhi|ghorahi|beni|kushma|waling|haldibari|dulegauda|baitadi|bhadrapur|syangja|parbat|myagdi|dang|n"&"uwakot|jhapa""), ""Tier 2"", TRUE, ""Tier 3"" )"),"Tier 2") -> Tier 2 | M7: Koshi | N7: **Gandaki** | O7: 7 | P7: 10 | Q7: 4 | R7: **21**
B8: =IFERROR(__xludf.DUMMYFUNCTION("""COMPUTED_VALUE"""),45893.178032407406) -> 45893.178 | C8: =IFERROR(__xludf.DUMMYFUNCTION("""COMPUTED_VALUE"""),"Martin 3 sole size 39 39 38") -> Martin 3 sole size 39 39 38 | D8: =IFERROR(__xludf.DUMMYFUNCTION("""COMPUTED_VALUE"""),"Laxmi Rai") -> Laxmi Rai | E8: =IFERROR(__xludf.DUMMYFUNCTION("""COMPUTED_VALUE""")," Shree antu, baral bhanjyang") -> Shree antu, baral bhanjyang | F8: =IFERROR(__xludf.DUMMYFUNCTION("""COMPUTED_VALUE"""),9.769723304E9) -> 9769723304 | G8: =IFERROR(__xludf.DUMMYFUNCTION("""COMPUTED_VALUE"""),1300.0) -> 1300 | H8: =IFERROR(__xludf.DUMMYFUNCTION("""COMPUTED_VALUE"""),4650.0) -> 4650 | I8: =IFERROR(__xludf.DUMMYFUNCTION("""COMPUTED_VALUE"""),220.63) -> 220.63 | J8: =IFERROR(__xludf.DUMMYFUNCTION("""COMPUTED_VALUE"""),"Delivered") -> Delivered | K8: =IFERROR(__xludf.DUMMYFUNCTION("""COMPUTED_VALUE"""),45898.376655092594) -> 45898.377 | L8: =IFERROR(__xludf.DUMMYFUNCTION("IFS( OR(REGEXMATCH(LOWER(E8), ""sirutar|sundarijal|sitapaila|duwakot|tikathali|bhaktapur|lalitpur|kathmandu|ktm|changunarayan|bageswari|ghalate|tinkune|balkot|tikathali""), REGEXMATCH(LOWER(E8), ""inside valley"")), ""Inside Valley"", REGEXMATCH(LOWER"&"(E8), ""dharan|pokhara|biratnagar|birgunj|narayanghat|itahari|hetauda|janakpur|madi""), ""Tier 1"", REGEXMATCH(LOWER(E8), ""nepalgunj|butwal|birtamod|dhangadhi|ghorahi|beni|kushma|waling|haldibari|dulegauda|baitadi|bhadrapur|syangja|parbat|myagdi|dang|n"&"uwakot|jhapa""), ""Tier 2"", TRUE, ""Tier 3"" )"),"Tier 3") -> Tier 3 | M8: Madhesh | N8: **Lumbini** | O8: 0 | P8: 10 | Q8: 8 | R8: **18**
